<mujoco model="simple_biped">
    <compiler angle="degree"/>

    <option timestep="0.0005"/>

    <!-- <asset>
        <hfield name="terrain" nrow="256" ncol="256" size="16 16 0.5 0.01"/>
    </asset> -->

    <visual>
        <headlight diffuse="0.6 0.6 0.6" ambient="0.3 0.3 0.3" specular="0.1 0.1 0.1"/>
        <rgba haze="0.15 0.25 0.35 1"/>
        <global azimuth="120" elevation="30" offwidth="800" offheight="600"/>
    </visual>

    <worldbody>
        <light name="sun" directional="true" dir="-1 -1 -2" castshadow="true"/>
        <camera name="track" pos="3 -3 1" xyaxes="1 1 0 0 0 1" mode="trackcom"/>

        <!-- Ground plane -->
        <geom name="ground" type="plane" size="50 50 0.1" rgba="0.2 0.3 0.4 1"/>
        
        <!-- Heightfield terrain -->
        <!-- <geom name="ground" type="hfield" hfield="terrain" rgba="0.2 0.3 0.4 1"/> -->




        <!-- Torso -->
        <!-- <body name="torso" pos="0 0 1.6"> -->
        <body name="torso" pos="0 0 0">
            <geom type="capsule" size="0.1 0.3" mass="8" rgba="0.8 0.2 0.2 1"/>
            <joint type="free"/>
            <site name="torso_site" pos="0 0 0" size="0.02" rgba="1 0 0 0.8" euler="0 0 180"/>
            

            <!-- Right leg -->
            <body name="right_hip_z" pos="0 -0.05 -0.25">
                <joint name="right_hip_z_j" type="hinge" axis="0 0 1" range="-20 20"/>
                <geom type="capsule" size="0.07 0.025" mass="0.1" rgba="0.2 0.2 0.8 1" pos="0 0.0 -0.025"  euler="-0 0 0" contype="0" conaffinity="0"/>
                <body name="right_hip_y" pos="0 -0.00 -0.05">
                    <joint name="right_hip_y_j" type="hinge" axis="1 0 0" range="-20 20"/>
                    <geom type="capsule" size="0.07 0.025" mass="0.1" rgba="0.2 0.2 0.8 1" pos="0 -0.025 0.0"  euler="90 0 0" contype="0" conaffinity="0"/>
                    <body name="right_thigh" pos="0 -0.05 -0.0">
                        <joint name="right_hip" type="hinge" axis="0 1 0" range="-60 60"/>
                        <geom type="capsule" size="0.07 0.3" mass="1" rgba="0.2 0.2 0.8 1" pos="0 0 -0.3" contype="0" conaffinity="0"/>
                        <!-- Right shin -->
                        <body name="right_shin" pos="0 0 -0.6">
                            <joint name="right_knee" type="hinge" axis="0 1 0" range="-120 -5"/>
                            <geom name="right_shin_geom" type="capsule" size="0.06 0.3" mass="1" rgba="0.2 0.2 0.8 1" pos="0 0 -0.3"/>
                            <body name="right_foot" pos="0 0 -0.6">
                                <joint name="right_foot_j" type="hinge" axis="0 1 0" range="-60 60"/>
                                <geom name="right_foot_geom" type="capsule" size="0.06 0.08" mass="0.1" rgba="0.2 0.2 0.8 1" pos="0 0 -0.0" euler="-0 90 0"
                                solref="0.001 1" solimp="0.99 0.99 0.001"/>
                            </body>
                        </body>
                    </body>
                </body>
            </body>
            <!-- Left leg -->
            <body name="left_hip_z" pos="0 0.05 -0.25">
                <joint name="left_hip_z_j" type="hinge" axis="0 0 1" range="-20 20"/>
                <geom type="capsule" size="0.07 0.025" mass="0.1" rgba="0.2 0.8 0.2 1" pos="0 0.0 -0.025"  euler="-0 0 0" contype="0" conaffinity="0"/>
                <body name="left_hip_y" pos="0 0.0 -0.05">
                    <joint name="left_hip_y_j" type="hinge" axis="1 0 0" range="-20 20"/>
                    <geom type="capsule" size="0.07 0.025" mass="0.1" rgba="0.2 0.8 0.2 1" pos="0 0.025 0.0"  euler="90 0 0" contype="0" conaffinity="0"/>
                    <!-- Left thigh -->
                    <body name="left_thigh" pos="0 0.05 -0.0">
                        <joint name="left_hip" type="hinge" axis="0 1 0" range="-120 120"/>
                        <geom type="capsule" size="0.07 0.3" mass="1" rgba="0.2 0.8 0.2 1" pos="0 0 -0.3" contype="0" conaffinity="0"/>
                        <!-- Left shin -->
                        <body name="left_shin" pos="0 0 -0.6">
                            <joint name="left_knee" type="hinge" axis="0 1 0" range="-120 -5"/>
                            <geom name="left_shin_geom" type="capsule" size="0.06 0.3" mass="1" rgba="0.2 0.8 0.2 1" pos="0 0 -0.3"/>
                            <body name="left_foot" pos="0 0 -0.6">
                                <joint name="left_foot_j" type="hinge" axis="0 1 0" range="-60 60"/>
                                <geom name="left_foot_geom" type="capsule" size="0.06 0.08" mass="0.1" rgba="0.2 0.2 0.8 1" pos="0 0 -0.0" euler="-0 90 0"
                                solref="0.001 1" solimp="0.99 0.99 0.001"/>
                            </body>
                        </body>
                    </body>
                </body>
            </body>
        </body>
    </worldbody>

    <keyframe>
        <key name="stand" qpos="0 0 1.55 1 0 0 0 0 0 0 0 0 0 0 0 0 0"/>
    </keyframe>

    <actuator>
        <motor joint="right_hip_z_j"/>
        <motor joint="right_hip_y_j"/>
        <motor joint="right_hip"/>
        <motor joint="right_knee"/>
        <motor joint="right_foot_j" />

        <motor joint="left_hip_z_j"/>
        <motor joint="left_hip_y_j"/>
        <motor joint="left_hip"/>
        <motor joint="left_knee"/>
        <motor joint="left_foot_j" />
    </actuator>

    <sensor>
        <gyro name="body_gyro" site="torso_site"/>
       <!-- <accelerometer name="body_acc" site="torso_site"/> -->
    </sensor>
    
</mujoco>